Workbook

Sheet DC หมวด A-D
B2: แผนแรงงานรายวัน DC หมวด A-D
B3: ข้อมูลเบื้องต้นสำหรับวางแผน | D3: จำนวนห้องทั้งหมด | E3: พื้นที่ห้องเฉลี่ย | F3: % แรงงานชาย | G3: ค่าแรงชาย/วัน | H3: ค่า OT ชาย/ชม. | I3: % แรงงานหญิง | J3: ค่าแรงหญิง/วัน | K3: ค่า OT หญิง/ชม. | L3: จำนวน OT/วัน | M3: จำนวนวัน/เดือน
D4: 1 | E4: 48399 | F4: 0.5 | G4: 350 | H4: =G4/8*1.5 -> 65.625 | I4: 0.5 | J4: 300 | K4: =J4/8*1.5 -> 56.25 | L4: 2 | M4: 26
B6: เดือนที่ (นับตามสัญญา) | I6: 1 | J6: 2 | K6: 3 | L6: 4 | M6: 5 | N6: 6 | O6: 7 | P6: 8 | Q6: 9 | R6: 10 | S6: 11 | T6: 12 | U6: 13 | V6: 14 | W6: 15
B7: เดือน | D7: 25235 | E7: 25263 | F7: 25294 | G7: 25324 | H7: 25355 | I7: 25385 | J7: 25416 | K7: 25447 | L7: 25477 | M7: 25508 | N7: 25538 | O7: 25569 | P7: 25600 | Q7: 25628 | R7: 25659 | S7: 25689 | T7: 25720 | U7: 25750 | V7: 25781 | W7: 25812
B9: หมวด A | C9: จำนวนแรงงาน | D9: 5 | E9: 5 | F9: 5 | G9: 5 | H9: =Backup!C33 -> 20 | I9: =Backup!D33 -> 29 | J9: =Backup!E33 -> 29 | K9: =Backup!F33 -> 29 | L9: =Backup!G33 -> 29 | M9: =Backup!H33 -> 29 | N9: =Backup!I33 -> 29 | O9: =Backup!J33 -> 29 | ... W9: =Backup!R33 -> 10 | Y9: Budget | Z9: ทำจริง (แรง) | AA9: คงเหลือ
C10: จำนวนแรงงานสะสม | D10: =D9 -> 5 | E10: =E9+D10 -> 10 | F10: =F9+E10 -> 15 | G10: =G9+F10 -> 20 | H10: =H9+G10 -> 40 | I10: =I9+H10 -> 69 | J10: =J9+I10 -> 98 | K10: =K9+J10 -> 127 | L10: =L9+K10 -> 156 | ... W10: =W9+V10 -> 418 | Y10: =(Y11/((($G$4+($H$4*$L$4))*$F$4)+(($J$4+($K$4*$L$4))*$I$4))) -> 2707.6364 | Z10: =SUM(D9:W9)*$M$4 -> 10868 | AA10: =Y10-Z10 -> -8160.3636 | AB10: แรง
C11: มูลค่าสะสม (บาท) | D11: =((($G$4+($H$4*$L$4))*$F$4)+(($J$4+($K$4*$L$4))*$I$4))*D10*$M$4 -> 58093.75 | E11: =((($G$4+($H$4*$L$4))*$F$4)+(($J$4+($K$4*$L$4))*$I$4))*E10*$M$4 -> 116187.5 | F11: =((($G$4+($H$4*$L$4))*$F$4)+(($J$4+($K$4*$L$4))*$I$4))*F10*$M$4 -> 174281.25 | G11: =((($G$4+($H$4*$L$4))*$F$4)+(($J$4+($K$4*$L$4))*$I$4))*G10*$M$4 -> 232375 | H11: =((($G$4+($H$4*$L$4))*$F$4)+(($J$4+($K$4*$L$4))*$I$4))*H10*$M$4 -> 464750 | I11: =((($G$4+($H$4*$L$4))*$F$4)+(($J$4+($K$4*$L$4))*$I$4))*I10*$M$4 -> 801693.75 | J11: =((($G$4+($H$4*$L$4))*$F$4)+(($J$4+($K$4*$L$4))*$I$4))*J10*$M$4 -> 1138637.5 | K11: =((($G$4+($H$4*$L$4))*$F$4)+(($J$4+($K$4*$L$4))*$I$4))*K10*$M$4 -> 1475581.2 | ... W11: =((($G$4+($H$4*$L$4))*$F$4)+(($J$4+($K$4*$L$4))*$I$4))*W10*$M$4 -> 4856637.5 | Y11: =25*$E$4 -> 1209975 | AA11: =Y11-W11 -> -3646662.5 | AB11: บาท
C12: Productivity (บาท/ตร.ม.) | D12: =D11/$E$4 -> 1.2003089 | E12: =E11/$E$4 -> 2.4006178 | F12: =F11/$E$4 -> 3.6009267 | G12: =G11/$E$4 -> 4.8012356 | H12: =H11/$E$4 -> 9.6024711 | I12: =I11/$E$4 -> 16.564263 | J12: =J11/$E$4 -> 23.526054 | K12: =K11/$E$4 -> 30.487846 | ... W12: =W11/$E$4 -> 100.34582 | Y12: =Y11/$E$4 -> 25 | AA12: =Y12-W12 -> -75.345823 | AB12: บาท/ตร.ม.
B14: หมวด B | C14: จำนวนแรงงาน | D14: 10 | E14: 10 | F14: 10 | G14: 10 | H14: =Backup!C38 -> 17 | I14: =Backup!D38 -> 24 | J14: =Backup!E38 -> 24 | K14: =Backup!F38 -> 24 | L14: =Backup!G38 -> 24 | M14: =Backup!H38 -> 24 | N14: =Backup!I38 -> 24 | O14: =Backup!J38 -> 18 | ... W14: =Backup!R38 -> 13 | Y14: Budget | Z14: ทำจริง (แรง) | AA14: คงเหลือ
C15: จำนวนแรงงานสะสม | D15: =D14 -> 10 | E15: =E14+D15 -> 20 | F15: =F14+E15 -> 30 | G15: =G14+F15 -> 40 | H15: =H14+G15 -> 57 | I15: =I14+H15 -> 81 | J15: =J14+I15 -> 105 | K15: =K14+J15 -> 129 | L15: =L14+K15 -> 153 | ... W15: =W14+V15 -> 350 | Y15: =Y16/((($G$4+($H$4*$L$4))*$F$4)+(($J$4+($K$4*$L$4))*$I$4)) -> 11372.073 | Z15: =SUM(D14:W14)*$M$4 -> 9100 | AA15: =Y15-Z15 -> 2272.0727 | AB15: แรง
C16: มูลค่าสะสม (บาท) | D16: =((($G$4+($H$4*$L$4))*$F$4)+(($J$4+($K$4*$L$4))*$I$4))*D15*$M$4 -> 116187.5 | E16: =((($G$4+($H$4*$L$4))*$F$4)+(($J$4+($K$4*$L$4))*$I$4))*E15*$M$4 -> 232375 | F16: =((($G$4+($H$4*$L$4))*$F$4)+(($J$4+($K$4*$L$4))*$I$4))*F15*$M$4 -> 348562.5 | G16: =((($G$4+($H$4*$L$4))*$F$4)+(($J$4+($K$4*$L$4))*$I$4))*G15*$M$4 -> 464750 | H16: =((($G$4+($H$4*$L$4))*$F$4)+(($J$4+($K$4*$L$4))*$I$4))*H15*$M$4 -> 662268.75 | I16: =((($G$4+($H$4*$L$4))*$F$4)+(($J$4+($K$4*$L$4))*$I$4))*I15*$M$4 -> 941118.75 | J16: =((($G$4+($H$4*$L$4))*$F$4)+(($J$4+($K$4*$L$4))*$I$4))*J15*$M$4 -> 1219968.8 | K16: =((($G$4+($H$4*$L$4))*$F$4)+(($J$4+($K$4*$L$4))*$I$4))*K15*$M$4 -> 1498818.8 | ... W16: =((($G$4+($H$4*$L$4))*$F$4)+(($J$4+($K$4*$L$4))*$I$4))*W15*$M$4 -> 4066562.5 | Y16: =105*$E$4 -> 5081895 | AA16: =Y16-W16 -> 1015332.5 | AB16: บาท
C17: Productivity (บาท/ตร.ม.) | D17: =D16/$E$4 -> 2.4006178 | E17: =E16/$E$4 -> 4.8012356 | F17: =F16/$E$4 -> 7.2018533 | G17: =G16/$E$4 -> 9.6024711 | H17: =H16/$E$4 -> 13.683521 | I17: =I16/$E$4 -> 19.445004 | J17: =J16/$E$4 -> 25.206487 | K17: =K16/$E$4 -> 30.967969 | ... W17: =W16/$E$4 -> 84.021622 | Y17: =Y16/$E$4 -> 105 | AA17: =Y17-W17 -> 20.978378 | AB17: บาท/ตร.ม.
B19: หมวด C | C19: จำนวนแรงงาน | D19: 0 | E19: 0 | F19: 0 | G19: 0 | H19: =Backup!C44 -> 4 | I19: =Backup!D44 -> 8 | J19: =Backup!E44 -> 12 | K19: =Backup!F44 -> 24 | L19: =Backup!G44 -> 56 | M19: =Backup!H44 -> 56 | N19: =Backup!I44 -> 56 | O19: =Backup!J44 -> 56 | ... W19: =Backup!R44 -> 4 | Y19: Budget | Z19: ทำจริง (แรง) | AA19: คงเหลือ
C20: จำนวนแรงงานสะสม | D20: =D19 -> 0 | E20: =E19+D20 -> 0 | F20: =F19+E20 -> 0 | G20: =G19+F20 -> 0 | H20: =H19+G20 -> 4 | I20: =I19+H20 -> 12 | J20: =J19+I20 -> 24 | K20: =K19+J20 -> 48 | L20: =L19+K20 -> 104 | ... W20: =W19+V20 -> 572 | Y20: =Y21/((($G$4+($H$4*$L$4))*$F$4)+(($J$4+($K$4*$L$4))*$I$4)) -> 24910.255 | Z20: =SUM(D19:W19)*$M$4 -> 14872 | AA20: =Y20-Z20 -> 10038.255 | AB20: แรง
C21: มูลค่าสะสม (บาท) | D21: =((($G$4+($H$4*$L$4))*$F$4)+(($J$4+($K$4*$L$4))*$I$4))*D20*$M$4 -> 0 | E21: =((($G$4+($H$4*$L$4))*$F$4)+(($J$4+($K$4*$L$4))*$I$4))*E20*$M$4 -> 0 | F21: =((($G$4+($H$4*$L$4))*$F$4)+(($J$4+($K$4*$L$4))*$I$4))*F20*$M$4 -> 0 | G21: =((($G$4+($H$4*$L$4))*$F$4)+(($J$4+($K$4*$L$4))*$I$4))*G20*$M$4 -> 0 | H21: =((($G$4+($H$4*$L$4))*$F$4)+(($J$4+($K$4*$L$4))*$I$4))*H20*$M$4 -> 46475 | I21: =((($G$4+($H$4*$L$4))*$F$4)+(($J$4+($K$4*$L$4))*$I$4))*I20*$M$4 -> 139425 | J21: =((($G$4+($H$4*$L$4))*$F$4)+(($J$4+($K$4*$L$4))*$I$4))*J20*$M$4 -> 278850 | K21: =((($G$4+($H$4*$L$4))*$F$4)+(($J$4+($K$4*$L$4))*$I$4))*K20*$M$4 -> 557700 | ... W21: =((($G$4+($H$4*$L$4))*$F$4)+(($J$4+($K$4*$L$4))*$I$4))*W20*$M$4 -> 6645925 | Y21: =230*$E$4 -> 11131770 | AA21: =Y21-W21 -> 4485845 | AB21: บาท
C22: Productivity (บาท/ตร.ม.) | D22: =D21/$E$4 -> 0 | E22: =E21/$E$4 -> 0 | F22: =F21/$E$4 -> 0 | G22: =G21/$E$4 -> 0 | H22: =H21/$E$4 -> 0.96024711 | I22: =I21/$E$4 -> 2.8807413 | J22: =J21/$E$4 -> 5.7614827 | K22: =K21/$E$4 -> 11.522965 | ... W22: =W21/$E$4 -> 137.31534 | Y22: =Y21/$E$4 -> 230 | AA22: =Y22-W22 -> 92.684663 | AB22: บาท/ตร.ม.
B24: หมวด D | C24: จำนวนแรงงาน | D24: 4 | E24: 4 | F24: 4 | G24: 4 | H24: =Backup!C47 -> 6 | I24: =Backup!D47 -> 10 | J24: =Backup!E47 -> 14 | K24: =Backup!F47 -> 18 | L24: =Backup!G47 -> 18 | M24: =Backup!H47 -> 18 | N24: =Backup!I47 -> 18 | O24: =Backup!J47 -> 18 | ... W24: =Backup!R47 -> 6 | Y24: Budget | Z24: ทำจริง (แรง) | AA24: คงเหลือ
C25: จำนวนแรงงานสะสม | D25: =D24 -> 4 | E25: =E24+D25 -> 8 | F25: =F24+E25 -> 12 | G25: =G24+F25 -> 16 | H25: =H24+G25 -> 22 | I25: =I24+H25 -> 32 | J25: =J24+I25 -> 46 | K25: =K24+J25 -> 64 | L25: =L24+K25 -> 82 | ... W25: =W24+V25 -> 256 | Y25: =Y26/((($G$4+($H$4*$L$4))*$F$4)+(($J$4+($K$4*$L$4))*$I$4)) -> 4332.2182 | Z25: =SUM(D24:W24)*$M$4 -> 6656 | AA25: =Y25-Z25 -> -2323.7818 | AB25: แรง
C26: มูลค่าสะสม (บาท) | D26: =((($G$4+($H$4*$L$4))*$F$4)+(($J$4+($K$4*$L$4))*$I$4))*D25*$M$4 -> 46475 | E26: =((($G$4+($H$4*$L$4))*$F$4)+(($J$4+($K$4*$L$4))*$I$4))*E25*$M$4 -> 92950 | F26: =((($G$4+($H$4*$L$4))*$F$4)+(($J$4+($K$4*$L$4))*$I$4))*F25*$M$4 -> 139425 | G26: =((($G$4+($H$4*$L$4))*$F$4)+(($J$4+($K$4*$L$4))*$I$4))*G25*$M$4 -> 185900 | H26: =((($G$4+($H$4*$L$4))*$F$4)+(($J$4+($K$4*$L$4))*$I$4))*H25*$M$4 -> 255612.5 | I26: =((($G$4+($H$4*$L$4))*$F$4)+(($J$4+($K$4*$L$4))*$I$4))*I25*$M$4 -> 371800 | J26: =((($G$4+($H$4*$L$4))*$F$4)+(($J$4+($K$4*$L$4))*$I$4))*J25*$M$4 -> 534462.5 | K26: =((($G$4+($H$4*$L$4))*$F$4)+(($J$4+($K$4*$L$4))*$I$4))*K25*$M$4 -> 743600 | ... W26: =((($G$4+($H$4*$L$4))*$F$4)+(($J$4+($K$4*$L$4))*$I$4))*W25*$M$4 -> 2974400 | Y26: =40*$E$4 -> 1935960 | AA26: =Y26-W26 -> -1038440 | AB26: บาท
C27: Productivity (บาท/ตร.ม.) | D27: =D26/$E$4 -> 0.96024711 | E27: =E26/$E$4 -> 1.9204942 | F27: =F26/$E$4 -> 2.8807413 | G27: =G26/$E$4 -> 3.8409885 | H27: =H26/$E$4 -> 5.2813591 | I27: =I26/$E$4 -> 7.6819769 | J27: =J26/$E$4 -> 11.042842 | K27: =K26/$E$4 -> 15.363954 | ... W27: =W26/$E$4 -> 61.455815 | Y27: =Y26/$E$4 -> 40 | AA27: =Y27-W27 -> -21.455815 | AB27: บาท/ตร.ม.
B29: รวมแรงงาน ชาย (คน) | D29: =(D9+D14+D19+D24)*$F$4 -> 9.5 | E29: =(E9+E14+E19+E24)*$F$4 -> 9.5 | F29: =(F9+F14+F19+F24)*$F$4 -> 9.5 | G29: =(G9+G14+G19+G24)*$F$4 -> 9.5 | H29: =(H9+H14+H19+H24)*$F$4 -> 23.5 | I29: =(I9+I14+I19+I24)*$F$4 -> 35.5 | J29: =(J9+J14+J19+J24)*$F$4 -> 39.5 | K29: =(K9+K14+K19+K24)*$F$4 -> 47.5 | ... W29: =(W9+W14+W19+W24)*$F$4 -> 16.5
B30: รวมแรงงาน หญิง (คน) | D30: =(D9+D14+D19+D24)*$I$4 -> 9.5 | E30: =(E9+E14+E19+E24)*$I$4 -> 9.5 | F30: =(F9+F14+F19+F24)*$I$4 -> 9.5 | G30: =(G9+G14+G19+G24)*$I$4 -> 9.5 | H30: =(H9+H14+H19+H24)*$I$4 -> 23.5 | I30: =(I9+I14+I19+I24)*$I$4 -> 35.5 | J30: =(J9+J14+J19+J24)*$I$4 -> 39.5 | K30: =(K9+K14+K19+K24)*$I$4 -> 47.5 | ... W30: =(W9+W14+W19+W24)*$I$4 -> 16.5
B31: รวมแรงงาน (คน) / เดือน | D31: =SUM(D29:D30) -> 19 | E31: =SUM(E29:E30) -> 19 | F31: =SUM(F29:F30) -> 19 | G31: =SUM(G29:G30) -> 19 | H31: =SUM(H29:H30) -> 47 | I31: =SUM(I29:I30) -> 71 | J31: =SUM(J29:J30) -> 79 | K31: =SUM(K29:K30) -> 95 | ... W31: =SUM(W29:W30) -> 33
B32: ค่าแรง / เดือน (บาท) | D32: =((D29*$G$4)+(D30*$J$4))*$M$4 -> 160550 | E32: =((E29*$G$4)+(E30*$J$4))*$M$4 -> 160550 | F32: =((F29*$G$4)+(F30*$J$4))*$M$4 -> 160550 | G32: =((G29*$G$4)+(G30*$J$4))*$M$4 -> 160550 | H32: =((H29*$G$4)+(H30*$J$4))*$M$4 -> 397150 | I32: =((I29*$G$4)+(I30*$J$4))*$M$4 -> 599950 | J32: =((J29*$G$4)+(J30*$J$4))*$M$4 -> 667550 | K32: =((K29*$G$4)+(K30*$J$4))*$M$4 -> 802750 | ... W32: =((W29*$G$4)+(W30*$J$4))*$M$4 -> 278850 | Y32: Budget | Z32: ทำจริง (แรง) | AA32: คงเหลือ
B33: OT / เดือน (บาท) | D33: =((D29*$H$4*$L$4)+(D30*$K$4*$L$4))*$M$4 -> 60206.25 | E33: =((E29*$H$4*$L$4)+(E30*$K$4*$L$4))*$M$4 -> 60206.25 | F33: =((F29*$H$4*$L$4)+(F30*$K$4*$L$4))*$M$4 -> 60206.25 | G33: =((G29*$H$4*$L$4)+(G30*$K$4*$L$4))*$M$4 -> 60206.25 | H33: =((H29*$H$4*$L$4)+(H30*$K$4*$L$4))*$M$4 -> 148931.25 | I33: =((I29*$H$4*$L$4)+(I30*$K$4*$L$4))*$M$4 -> 224981.25 | J33: =((J29*$H$4*$L$4)+(J30*$K$4*$L$4))*$M$4 -> 250331.25 | K33: =((K29*$H$4*$L$4)+(K30*$K$4*$L$4))*$M$4 -> 301031.25 | ... W33: =((W29*$H$4*$L$4)+(W30*$K$4*$L$4))*$M$4 -> 104568.75 | Y33: =Y34/((($G$4+($H$4*$L$4))*$F$4)+(($J$4+($K$4*$L$4))*$I$4)) -> 43322.182 | Z33: =SUM(D29:W30)*$M$4 -> 41496 | AA33: =Y33-Z33 -> 1826.1818 | AB33: แรง
B34: รวมค่าแรง + OT / เดือน (บาท) | D34: =SUM(D32:D33) -> 220756.25 | E34: =SUM(E32:E33) -> 220756.25 | F34: =SUM(F32:F33) -> 220756.25 | G34: =SUM(G32:G33) -> 220756.25 | H34: =SUM(H32:H33) -> 546081.25 | I34: =SUM(I32:I33) -> 824931.25 | J34: =SUM(J32:J33) -> 917881.25 | K34: =SUM(K32:K33) -> 1103781.2 | ... W34: =SUM(W32:W33) -> 383418.75 | Y34: =400*$E$4 -> 19359600 | AA34: =Y34-W35 -> 816075 | AB34: บาท
B35: รวมค่าแรงสะสม (บาท) | D35: =D34 -> 220756.25 | E35: =E34+D35 -> 441512.5 | F35: =F34+E35 -> 662268.75 | G35: =G34+F35 -> 883025 | H35: =H34+G35 -> 1429106.2 | I35: =I34+H35 -> 2254037.5 | J35: =J34+I35 -> 3171918.8 | K35: =K34+J35 -> 4275700 | L35: =L34+K35 -> 5751281.2 | ... W35: =W34+V35 -> 18543525 | Y35: =Y34/$E$4 -> 400 | AA35: =Y35-W36 -> 16.861402 | AB35: บาท/ตร.ม.
B36: Productivity (บาท/ตร.ม.) | D36: =D35/$E$4 -> 4.5611738 | E36: =E35/$E$4 -> 9.1223476 | F36: =F35/$E$4 -> 13.683521 | G36: =G35/$E$4 -> 18.244695 | H36: =H35/$E$4 -> 29.527599 | I36: =I35/$E$4 -> 46.571985 | J36: =J35/$E$4 -> 65.536865 | K36: =K35/$E$4 -> 88.342734 | ... W36: =W35/$E$4 -> 383.1386
B38: ทำจริง | C38: งวดวันที่ 1 - 15 | D38: 87850 | E38: 100968.76 | F38: 76234.42 | G38: 130154.08 | H38: 216440.38
C39: งวดวันที่ 16 - 31 | D39: 86839.07 | E39: 86681.27 | F39: 84178.14 | G39: 193995.94 | H39: 273808.18
C40: รวมค่าแรงต่อเดือน | D40: =D38+D39 -> 174689.07 | E40: =E38+E39 -> 187650.03 | F40: =F38+F39 -> 160412.56 | G40: =G38+G39 -> 324150.02 | H40: =H38+H39 -> 490248.56 | I40: =I38+I39 -> 0
C41: รวมค่าแรงสะสม | D41: =D40 -> 174689.07 | E41: =E40+D41 -> 362339.1 | F41: =F40+E41 -> 522751.66 | G41: =G40+F41 -> 846901.68 | H41: =H40+G41 -> 1337150.2 | I41: =I40+H41 -> 1337150.2
C42: Productivity (บาท/ตร.ม.) | D42: =D41/$E$4 -> 3.6093529 | E42: =E41/$E$4 -> 7.4864997 | F42: =F41/$E$4 -> 10.800877 | G42: =G41/$E$4 -> 17.49833 | H42: =H41/$E$4 -> 27.627642 | I42: =I41/$E$4 -> 27.627642
B44: คงเหลือ | C44: คงเหลือต่อเดือน | D44: =D34-D40 -> 46067.18 | E44: =E34-E40 -> 33106.22 | F44: =F34-F40 -> 60343.69 | G44: =G34-G40 -> -103393.77 | H44: =H34-H40 -> 55832.69 | I44: =I34-I40 -> 824931.25
C45: คงเหลือสะสม | D45: =D44 -> 46067.18 | E45: =E44+D45 -> 79173.4 | F45: =F44+E45 -> 139517.09 | G45: =G44+F45 -> 36123.32 | H45: =H44+G45 -> 91956.01 | I45: =I44+H45 -> 916887.26
C46: คงเหลือ (บาท/ตร.ม.) | D46: =D45/$E$4 -> 0.95182091 | E46: =E45/$E$4 -> 1.6358478 | F46: =F45/$E$4 -> 2.8826441 | G46: =G45/$E$4 -> 0.74636501 | H46: =H45/$E$4 -> 1.8999568 | I46: =I45/$E$4 -> 18.944343

Sheet Backup
A2: MANPOWER
A3: Life Ratchada-Rama 9
A5: ลำดับ | B5: ตำแหน่งงาน | C5: จำนวนแรงงาน: เดือน | S5: หมายเหตุ
C6: M1 | D6: M2 | E6: M3 | F6: M4 | G6: M5 | H6: M6 | I6: M7 | J6: M8 | K6: M9 | L6: M10 | M6: M11 | N6: M12 | O6: M13 | P6: M14 | Q6: M15 | R6: M16
B7: งานเสาเข็ม อาคาร A-E
B8: Sub-Structure
B9: อาคาร A-E
B10: Super-Structure
B11: อาคาร A-E
B12: Arhitech Work
B13: ประกอบห้องพักอาคาร A-D
B14: อาคาร E
B15: External Work
B16: Sink บ่อ WWTP
B17: Drainage/Fence /Road
B18: End Product & QA Pass
... B22: Worker
A23: A | B23: DC SUPPLY
A24: 1 | B24: Security | C24: 2 | D24: 2 | E24: 2 | F24: 2 | G24: 2 | H24: 2 | I24: 2 | J24: 2 | K24: 2 | L24: 2 | M24: 2 | N24: 2 | O24: 2 | P24: 2 | Q24: 2 | R24: 2 | S24: Supplier | T24: =SUM(C24:R24) -> 32
A25: 2 | B25: Pick-up Driver | C25: 1 | D25: 1 | E25: 1 | F25: 1 | G25: 1 | H25: 1 | I25: 1 | J25: 1 | K25: 1 | L25: 1 | M25: 1 | N25: 1 | O25: 1 | P25: 1 | Q25: 1 | R25: 1 | S25: DC หมวด A5.3 | T25: =SUM(C25:R25) -> 16
A26: 3 | B26: Tower Crane Operator | C26: 4 | D26: 4 | E26: 4 | F26: 4 | G26: 4 | H26: 4 | I26: 4 | J26: 4 | K26: 4 | L26: 4 | M26: 4 | S26: DC หมวด A5.1 | T26: =SUM(C26:R26) -> 44
A27: 4 | B27: คนบอกเครน | C27: 4 | D27: 4 | E27: 4 | F27: 4 | G27: 4 | H27: 4 | I27: 4 | J27: 4 | K27: 4 | L27: 4 | M27: 4 | S27: DC หมวด A5.1 | T27: =SUM(C27:R27) -> 44
A28: 5 | B28: Hoist Operator | L28: 4 | M28: 4 | N28: 4 | O28: 4 | P28: 4 | Q28: 4 | R28: 4 | S28: DC หมวด A5.2 | T28: =SUM(C28:R28) -> 28
A29: 6 | B29: Survey Helper | C29: 6 | D29: 15 | E29: 15 | F29: 15 | G29: 15 | H29: 15 | I29: 15 | J29: 15 | K29: 15 | L29: 15 | M29: 15 | N29: 15 | O29: 15 | S29: DC หมวด A1 | T29: =SUM(C29:R29) -> 186
A30: 7 | B30: Store Helper | C30: 2 | D30: 2 | E30: 2 | F30: 2 | G30: 2 | H30: 2 | I30: 2 | J30: 2 | K30: 2 | L30: 2 | M30: 2 | N30: 2 | O30: 2 | P30: 2 | Q30: 2 | R30: 2 | S30: DC หมวด A2 | T30: =SUM(C30:R30) -> 32
A31: 8 | B31: Electrician /Machanic | C31: 1 | D31: 1 | E31: 1 | F31: 1 | G31: 1 | H31: 1 | I31: 1 | J31: 1 | K31: 1 | L31: 1 | M31: 1 | N31: 1 | O31: 1 | P31: 1 | Q31: 1 | R31: 1 | S31: DC หมวด A3 | T31: =SUM(C31:R31) -> 16
A32: 9 | B32: แม่บ้านประจำสำนักงานสนาม | C32: 2 | D32: 2 | E32: 2 | F32: 2 | G32: 2 | H32: 2 | I32: 2 | J32: 2 | K32: 2 | L32: 2 | M32: 2 | N32: 2 | O32: 2 | P32: 2 | Q32: 2 | R32: 2 | S32: DC หมวด A4 | T32: =SUM(C32:R32) -> 32
B33: รวม DC หมวด A | C33: =SUM(C25:C32) -> 20 | D33: =SUM(D25:D32) -> 29 | E33: =SUM(E25:E32) -> 29 | F33: =SUM(F25:F32) -> 29 | G33: =SUM(G25:G32) -> 29 | H33: =SUM(H25:H32) -> 29 | I33: =SUM(I25:I32) -> 29 | J33: =SUM(J25:J32) -> 29 | ... R33: =SUM(R25:R32) -> 10 | T33: =SUM(C33:R33) -> 398
A34: 10 | B34: Labour (Cleanning) | C34: 8 | D34: 8 | E34: 8 | F34: 8 | G34: 8 | H34: 8 | I34: 8 | J34: 8 | K34: 8 | L34: 8 | M34: 8 | N34: 8 | O34: 8 | P34: 8 | Q34: 8 | R34: 8 | S34: DC หมวด B3 | T34: =SUM(C34:R34) -> 128
A35: 11 | B35: Labour (Material Handering) | C35: 5 | D35: 6 | E35: 6 | F35: 6 | G35: 6 | H35: 6 | I35: 6 | J35: 6 | K35: 6 | L35: 6 | M35: 6 | N35: 6 | O35: 6 | P35: 6 | Q35: 6 | R35: 5 | S35: DC หมวด B5 | T35: =SUM(C35:R35) -> 94
A36: 12 | B36: กรรมกรงานโครงสร้างใต้ดิน | D36: 6 | E36: 6 | F36: 6 | G36: 6 | H36: 6 | I36: 6 | S36: DC หมวด B1 | T36: =SUM(C36:R36) -> 36
A37: 13 | B37: ทีมจราจรในหน่วยงานและชุมชน | C37: 4 | D37: 4 | E37: 4 | F37: 4 | G37: 4 | H37: 4 | I37: 4 | J37: 4 | K37: 4 | L37: 4 | M37: 4 | N37: 4 | O37: 4 | S37: DC หมวด B6 | T37: =SUM(C37:R37) -> 52
B38: รวม DC หมวด B | C38: =SUM(C34:C37) -> 17 | D38: =SUM(D34:D37) -> 24 | E38: =SUM(E34:E37) -> 24 | F38: =SUM(F34:F37) -> 24 | G38: =SUM(G34:G37) -> 24 | H38: =SUM(H34:H37) -> 24 | I38: =SUM(I34:I37) -> 24 | J38: =SUM(J34:J37) -> 18 | ... R38: =SUM(R34:R37) -> 13 | T38: =SUM(C38:R38) -> 310
A39: 14 | B39: กรรมกรทำความสะอาดตามชั้น | G39: 12 | H39: 12 | I39: 12 | J39: 12 | K39: 12 | L39: 12 | M39: 12 | N39: 12 | O39: 12 | P39: 12 | Q39: 12 | S39: DC หมวด C1 | T39: =SUM(C39:R39) -> 132
A40: 15 | B40: กรรมกรขึ้นวัสดุ - ลงขยะ | C40: 4 | D40: 8 | E40: 12 | F40: 16 | G40: 16 | H40: 16 | I40: 16 | J40: 16 | K40: 16 | L40: 16 | M40: 16 | N40: 16 | O40: 16 | P40: 12 | Q40: 8 | R40: 4 | S40: DC หมวด C2 | T40: =SUM(C40:R40) -> 208
A41: 16 | B41: กรรมกรงานโครงสร้างอาคาร | F41: 8 | G41: 8 | H41: 8 | I41: 8 | J41: 8 | S41: DC หมวด C5 | T41: =SUM(C41:R41) -> 40
A42: 17 | B42: กรรมกรงานสถาปัตย์อาคาร | G42: 8 | H42: 8 | I42: 8 | J42: 8 | K42: 8 | L42: 8 | M42: 8 | N42: 8 | O42: 8 | S42: DC หมวด C6 | T42: =SUM(C42:R42) -> 72
A43: 18 | B43: กรรมกรงานบริการอื่นๆในตัวอาคาร | G43: 12 | H43: 12 | I43: 12 | J43: 12 | K43: 12 | L43: 12 | M43: 12 | N43: 12 | O43: 12 | P43: 12 | S43: DC หมวด C7 | T43: =SUM(C43:R43) -> 120
B44: รวม DC หมวด C | C44: =SUM(C39:C43) -> 4 | D44: =SUM(D39:D43) -> 8 | E44: =SUM(E39:E43) -> 12 | F44: =SUM(F39:F43) -> 24 | G44: =SUM(G39:G43) -> 56 | H44: =SUM(H39:H43) -> 56 | I44: =SUM(I39:I43) -> 56 | J44: =SUM(J39:J43) -> 56 | ... R44: =SUM(R39:R43) -> 4 | T44: =SUM(C44:R44) -> 572
A45: 19 | B45: Worker (Safety / Protection) | C45: 4 | D45: 8 | E45: 12 | F45: 16 | G45: 16 | H45: 16 | I45: 16 | J45: 16 | K45: 16 | L45: 16 | M45: 16 | N45: 16 | O45: 16 | P45: 12 | Q45: 8 | R45: 4 | S45: DC หมวด D3 | T45: =SUM(C45:R45) -> 208
...

Sheet Feb26
B2: จำนวนแรงงาน DC แยกตามหมวดงาน ประจำเดือน กุมภาพันธ์ 2569
B3: หมวดงาน | D3: หมวดงานย่อย | F3: จำนวนแรงงาน (คน) | M3: รวม
M4: หมวดงานย่อย | O4: หมวดงาน
F5: A | G5: B | H5: C | I5: D | J5: E | K5: LA | L5: กองกลาง | M5: จำนวนคน | N5: % | O5: จำนวนคน | P5: %
B6: A | C6: งานประจำในไซต์งาน | D6: A1 | E6: งานเซอร์เวย์ / ตีไลน์ | L6: 3 | M6: =SUM(F6:L6) -> 3 | N6: =M6/$M$91 -> 0.15789474 | O6: =SUM(M6:M13) -> 5 | P6: =O6/O91 -> 0.26315789
D7: A2 | E7: งานสโตร์ / เช็กเกอร์ | M7: =SUM(F7:L7) -> 0 | N7: =M7/$M$91 -> 0
D8: A3 | E8: งานซ่อมบำรุง / บริการหน้างาน (ไฟฟ้า, ประปา) | L8: 1 | M8: =SUM(F8:L8) -> 1 | N8: =M8/$M$91 -> 0.052631579
D9: A4 | E9: งานแม่บ้าน / ทำความสะอาด | L9: 1 | M9: =SUM(F9:L9) -> 1 | N9: =M9/$M$91 -> 0.052631579
D10: A5 | E10: งานขับเครน /บอกเครน /เครื่องจักร /รถยนต์ | M10: =SUM(F10:L10) -> 0 | N10: =M10/$M$91 -> 0
E11: A5.1 - งานขับเครน / บอกเครน | M11: =SUM(F11:L11) -> 0 | N11: =M11/$M$91 -> 0
E12: A5.2 - ขับเครื่องจักร (ลิฟต์ / โฟล์คลิฟต์ / แบ็กโฮ ฯลฯ) | M12: =SUM(F12:L12) -> 0 | N12: =M12/$M$91 -> 0
E13: A5.3 - ขับรถยนต์ | M13: =SUM(F13:L13) -> 0 | N13: =M13/$M$91 -> 0
B14: B | C14: งานพื้นที่บริเวณชั้น 1 | D14: B1 | E14: งานป้องกันดินพัง / งานใต้ดิน | M14: =SUM(F14:L14) -> 0 | N14: =M14/$M$91 -> 0 | O14: =SUM(M14:M40) -> 10 | P14: =O14/O91 -> 0.52631579
E15: B1.1 - งานระบบป้องกันดินพัง | M15: =SUM(F15:L15) -> 0 | N15: =M15/$M$91 -> 0
E16: B1.2 - งานโครงสร้างใต้ดิน | M16: =SUM(F16:L16) -> 0 | N16: =M16/$M$91 -> 0
D17: B2 | E17: งานจัดเตรียมพื้นที่บริเวณชั้น 1 | M17: =SUM(F17:L17) -> 0 | N17: =M17/$M$91 -> 0
E18: B2.1 - งานเตรียมการ สำนักงาน, สโตร์, ห้องน้ำ, ป้าย, รั้ว, ป้อม, ประตู | L18: 10 | M18: =SUM(F18:L18) -> 10 | N18: =M18/$M$91 -> 0.52631579
E19: B2.2 - งานเตรียมพื้นที่กองวัสดุ / เหล็ก / ไม้แบบ / Silo อื่น ๆ | M19: =SUM(F19:L19) -> 0 | N19: =M19/$M$91 -> 0
E20: B2.3 - งานติดตั้งอุปกรณ์สำนักงาน / กล้องวงจรปิด | M20: =SUM(F20:L20) -> 0 | N20: =M20/$M$91 -> 0
E21: B2.4 - งานเตรียมพื้นที่บริเวณรับประทานอาหาร, ลานปูน, ถนน, ทางเดิน, หลังคาคลุม | M21: =SUM(F21:L21) -> 0 | N21: =M21/$M$91 -> 0
E22: B2.5 - งานจัดเรียงวัสดุให้เป็นระเบียบ | M22: =SUM(F22:L22) -> 0 | N22: =M22/$M$91 -> 0
E23: B2.6 - งานปูแผ่นเหล็กทางเดิน | M23: =SUM(F23:L23) -> 0 | N23: =M23/$M$91 -> 0
E24: B2.7 - งานตั้ง TC / ลิฟต์ชั่วคราว / Silo | M24: =SUM(F24:L24) -> 0 | N24: =M24/$M$91 -> 0
E25: B2.8 - งานเทคอนกรีตชั่วคราวบริเวณพื้นที่ชั้น 1 | M25: =SUM(F25:L25) -> 0 | N25: =M25/$M$91 -> 0
E26: B2.9 - งานจัดเตรียมอื่น ๆ | M26: =SUM(F26:L26) -> 0 | N26: =M26/$M$91 -> 0
D27: B3 | E27: งานความสะอาดบริเวณชั้น 1 | M27: =SUM(F27:L27) -> 0 | N27: =M27/$M$91 -> 0
E28: B3.1 - ทำความสะอาดบริเวณชั้น 1 | M28: =SUM(F28:L28) -> 0 | N28: =M28/$M$91 -> 0
E29: B3.2 - สูบน้ำ / ล้างล้อ / กวาดถนน | M29: =SUM(F29:L29) -> 0 | N29: =M29/$M$91 -> 0
D30: B4 | E30: งานเก็บขยะ / ขนขยะ บริเวณชั้น 1 | M30: =SUM(F30:L30) -> 0 | N30: =M30/$M$91 -> 0
D31: B5 | E31: งานขนย้ายวัสดุบริเวณชั้น 1 | M31: =SUM(F31:L31) -> 0 | N31: =M31/$M$91 -> 0
E32: B5.1 - รับวัสดุ / ขนวัสดุลงจากรถ | M32: =SUM(F32:L32) -> 0 | N32: =M32/$M$91 -> 0
E33: B5.2 - ส่งวัสดุขึ้นรถขนส่ง ส่งกลับร้านค้า / DSC | M33: =SUM(F33:L33) -> 0 | N33: =M33/$M$91 -> 0
E34: B5.3 - ขนย้ายวัสดุในโครงการ | M34: =SUM(F34:L34) -> 0 | N34: =M34/$M$91 -> 0
D35: B6 | E35: งานบริการอื่น ๆ บริเวณชั้น 1 | M35: =SUM(F35:L35) -> 0 | N35: =M35/$M$91 -> 0
E36: B6.1 - งานโบกรถ / จราจร | M36: =SUM(F36:L36) -> 0 | N36: =M36/$M$91 -> 0
E37: B6.2 - งานทาสีกันสนิมเหล็กกล่อง / แป๊บกลม | M37: =SUM(F37:L37) -> 0 | N37: =M37/$M$91 -> 0
E38: B6.3 - งานสำนักงานขาย | M38: =SUM(F38:L38) -> 0 | N38: =M38/$M$91 -> 0
E39: B6.4 - งานทำห้องเก็บวัสดุ / ห้องตัวอย่าง Mockup | M39: =SUM(F39:L39) -> 0 | N39: =M39/$M$91 -> 0
E40: B6.5 - งานอื่น ๆ บริเวณชั้น 1 | M40: =SUM(F40:L40) -> 0 | N40: =M40/$M$91 -> 0
B41: C | C41: งานพื้นที่ในตัวอาคาร | D41: C1 | E41: งานความสะอาดตามชั้น | M41: =SUM(F41:L41) -> 0 | N41: =M41/$M$91 -> 0 | O41: =SUM(M41:M58) -> 0 | P41: =O41/O91 -> 0
...

Sheet Mar26
B2: จำนวนแรงงาน DC แยกตามหมวดงาน ประจำเดือน มีนาคม 2569
B3: หมวดงาน | D3: หมวดงานย่อย | F3: จำนวนแรงงาน (คน) | M3: รวม
M4: หมวดงานย่อย | O4: หมวดงาน
F5: A | G5: B | H5: C | I5: D | J5: E | K5: LA | L5: กองกลาง | M5: จำนวนคน | N5: % | O5: จำนวนคน | P5: %
B6: A | C6: งานประจำในไซต์งาน | D6: A1 | E6: งานเซอร์เวย์ / ตีไลน์ | L6: 3 | M6: =SUM(F6:L6) -> 3 | N6: =M6/$M$91 -> 0.15789474 | O6: =SUM(M6:M13) -> 5 | P6: =O6/O91 -> 0.26315789
D7: A2 | E7: งานสโตร์ / เช็กเกอร์ | M7: =SUM(F7:L7) -> 0 | N7: =M7/$M$91 -> 0
D8: A3 | E8: งานซ่อมบำรุง / บริการหน้างาน (ไฟฟ้า, ประปา) | L8: 1 | M8: =SUM(F8:L8) -> 1 | N8: =M8/$M$91 -> 0.052631579
D9: A4 | E9: งานแม่บ้าน / ทำความสะอาด | L9: 1 | M9: =SUM(F9:L9) -> 1 | N9: =M9/$M$91 -> 0.052631579
D10: A5 | E10: งานขับเครน /บอกเครน /เครื่องจักร /รถยนต์ | M10: =SUM(F10:L10) -> 0 | N10: =M10/$M$91 -> 0
E11: A5.1 - งานขับเครน / บอกเครน | M11: =SUM(F11:L11) -> 0 | N11: =M11/$M$91 -> 0
E12: A5.2 - ขับเครื่องจักร (ลิฟต์ / โฟล์คลิฟต์ / แบ็กโฮ ฯลฯ) | M12: =SUM(F12:L12) -> 0 | N12: =M12/$M$91 -> 0
E13: A5.3 - ขับรถยนต์ | M13: =SUM(F13:L13) -> 0 | N13: =M13/$M$91 -> 0
B14: B | C14: งานพื้นที่บริเวณชั้น 1 | D14: B1 | E14: งานป้องกันดินพัง / งานใต้ดิน | M14: =SUM(F14:L14) -> 0 | N14: =M14/$M$91 -> 0 | O14: =SUM(M14:M40) -> 10 | P14: =O14/O91 -> 0.52631579
E15: B1.1 - งานระบบป้องกันดินพัง | M15: =SUM(F15:L15) -> 0 | N15: =M15/$M$91 -> 0
E16: B1.2 - งานโครงสร้างใต้ดิน | M16: =SUM(F16:L16) -> 0 | N16: =M16/$M$91 -> 0
D17: B2 | E17: งานจัดเตรียมพื้นที่บริเวณชั้น 1 | M17: =SUM(F17:L17) -> 0 | N17: =M17/$M$91 -> 0
E18: B2.1 - งานเตรียมการ สำนักงาน, สโตร์, ห้องน้ำ, ป้าย, รั้ว, ป้อม, ประตู | L18: 10 | M18: =SUM(F18:L18) -> 10 | N18: =M18/$M$91 -> 0.52631579
E19: B2.2 - งานเตรียมพื้นที่กองวัสดุ / เหล็ก / ไม้แบบ / Silo อื่น ๆ | M19: =SUM(F19:L19) -> 0 | N19: =M19/$M$91 -> 0
E20: B2.3 - งานติดตั้งอุปกรณ์สำนักงาน / กล้องวงจรปิด | M20: =SUM(F20:L20) -> 0 | N20: =M20/$M$91 -> 0
E21: B2.4 - งานเตรียมพื้นที่บริเวณรับประทานอาหาร, ลานปูน, ถนน, ทางเดิน, หลังคาคลุม | M21: =SUM(F21:L21) -> 0 | N21: =M21/$M$91 -> 0
E22: B2.5 - งานจัดเรียงวัสดุให้เป็นระเบียบ | M22: =SUM(F22:L22) -> 0 | N22: =M22/$M$91 -> 0
E23: B2.6 - งานปูแผ่นเหล็กทางเดิน | M23: =SUM(F23:L23) -> 0 | N23: =M23/$M$91 -> 0
E24: B2.7 - งานตั้ง TC / ลิฟต์ชั่วคราว / Silo | M24: =SUM(F24:L24) -> 0 | N24: =M24/$M$91 -> 0
E25: B2.8 - งานเทคอนกรีตชั่วคราวบริเวณพื้นที่ชั้น 1 | M25: =SUM(F25:L25) -> 0 | N25: =M25/$M$91 -> 0
E26: B2.9 - งานจัดเตรียมอื่น ๆ | M26: =SUM(F26:L26) -> 0 | N26: =M26/$M$91 -> 0
D27: B3 | E27: งานความสะอาดบริเวณชั้น 1 | M27: =SUM(F27:L27) -> 0 | N27: =M27/$M$91 -> 0
E28: B3.1 - ทำความสะอาดบริเวณชั้น 1 | M28: =SUM(F28:L28) -> 0 | N28: =M28/$M$91 -> 0
E29: B3.2 - สูบน้ำ / ล้างล้อ / กวาดถนน | M29: =SUM(F29:L29) -> 0 | N29: =M29/$M$91 -> 0
D30: B4 | E30: งานเก็บขยะ / ขนขยะ บริเวณชั้น 1 | M30: =SUM(F30:L30) -> 0 | N30: =M30/$M$91 -> 0
D31: B5 | E31: งานขนย้ายวัสดุบริเวณชั้น 1 | M31: =SUM(F31:L31) -> 0 | N31: =M31/$M$91 -> 0
E32: B5.1 - รับวัสดุ / ขนวัสดุลงจากรถ | M32: =SUM(F32:L32) -> 0 | N32: =M32/$M$91 -> 0
E33: B5.2 - ส่งวัสดุขึ้นรถขนส่ง ส่งกลับร้านค้า / DSC | M33: =SUM(F33:L33) -> 0 | N33: =M33/$M$91 -> 0
E34: B5.3 - ขนย้ายวัสดุในโครงการ | M34: =SUM(F34:L34) -> 0 | N34: =M34/$M$91 -> 0
D35: B6 | E35: งานบริการอื่น ๆ บริเวณชั้น 1 | M35: =SUM(F35:L35) -> 0 | N35: =M35/$M$91 -> 0
E36: B6.1 - งานโบกรถ / จราจร | M36: =SUM(F36:L36) -> 0 | N36: =M36/$M$91 -> 0
E37: B6.2 - งานทาสีกันสนิมเหล็กกล่อง / แป๊บกลม | M37: =SUM(F37:L37) -> 0 | N37: =M37/$M$91 -> 0
E38: B6.3 - งานสำนักงานขาย | M38: =SUM(F38:L38) -> 0 | N38: =M38/$M$91 -> 0
E39: B6.4 - งานทำห้องเก็บวัสดุ / ห้องตัวอย่าง Mockup | M39: =SUM(F39:L39) -> 0 | N39: =M39/$M$91 -> 0
E40: B6.5 - งานอื่น ๆ บริเวณชั้น 1 | M40: =SUM(F40:L40) -> 0 | N40: =M40/$M$91 -> 0
B41: C | C41: งานพื้นที่ในตัวอาคาร | D41: C1 | E41: งานความสะอาดตามชั้น | M41: =SUM(F41:L41) -> 0 | N41: =M41/$M$91 -> 0 | O41: =SUM(M41:M58) -> 0 | P41: =O41/O91 -> 0
...

Sheet Apr26
B2: จำนวนแรงงาน DC แยกตามหมวดงาน ประจำเดือน เมษายน 2569
B3: หมวดงาน | D3: หมวดงานย่อย | F3: จำนวนแรงงาน (คน) | M3: รวม
M4: หมวดงานย่อย | O4: หมวดงาน
F5: A | G5: B | H5: C | I5: D | J5: E | K5: LA | L5: กองกลาง | M5: จำนวนคน | N5: % | O5: จำนวนคน | P5: %
B6: A | C6: งานประจำในไซต์งาน | D6: A1 | E6: งานเซอร์เวย์ / ตีไลน์ | L6: 3 | M6: =SUM(F6:L6) -> 3 | N6: =M6/$M$91 -> 0.15789474 | O6: =SUM(M6:M13) -> 5 | P6: =O6/O91 -> 0.26315789
D7: A2 | E7: งานสโตร์ / เช็กเกอร์ | M7: =SUM(F7:L7) -> 0 | N7: =M7/$M$91 -> 0
D8: A3 | E8: งานซ่อมบำรุง / บริการหน้างาน (ไฟฟ้า, ประปา) | L8: 1 | M8: =SUM(F8:L8) -> 1 | N8: =M8/$M$91 -> 0.052631579
D9: A4 | E9: งานแม่บ้าน / ทำความสะอาด | L9: 1 | M9: =SUM(F9:L9) -> 1 | N9: =M9/$M$91 -> 0.052631579
D10: A5 | E10: งานขับเครน /บอกเครน /เครื่องจักร /รถยนต์ | M10: =SUM(F10:L10) -> 0 | N10: =M10/$M$91 -> 0
E11: A5.1 - งานขับเครน / บอกเครน | M11: =SUM(F11:L11) -> 0 | N11: =M11/$M$91 -> 0
E12: A5.2 - ขับเครื่องจักร (ลิฟต์ / โฟล์คลิฟต์ / แบ็กโฮ ฯลฯ) | M12: =SUM(F12:L12) -> 0 | N12: =M12/$M$91 -> 0
E13: A5.3 - ขับรถยนต์ | M13: =SUM(F13:L13) -> 0 | N13: =M13/$M$91 -> 0
B14: B | C14: งานพื้นที่บริเวณชั้น 1 | D14: B1 | E14: งานป้องกันดินพัง / งานใต้ดิน | M14: =SUM(F14:L14) -> 0 | N14: =M14/$M$91 -> 0 | O14: =SUM(M14:M40) -> 10 | P14: =O14/O91 -> 0.52631579
E15: B1.1 - งานระบบป้องกันดินพัง | M15: =SUM(F15:L15) -> 0 | N15: =M15/$M$91 -> 0
E16: B1.2 - งานโครงสร้างใต้ดิน | M16: =SUM(F16:L16) -> 0 | N16: =M16/$M$91 -> 0
D17: B2 | E17: งานจัดเตรียมพื้นที่บริเวณชั้น 1 | M17: =SUM(F17:L17) -> 0 | N17: =M17/$M$91 -> 0
E18: B2.1 - งานเตรียมการ สำนักงาน, สโตร์, ห้องน้ำ, ป้าย, รั้ว, ป้อม, ประตู | L18: 5 | M18: =SUM(F18:L18) -> 5 | N18: =M18/$M$91 -> 0.26315789
E19: B2.2 - งานเตรียมพื้นที่กองวัสดุ / เหล็ก / ไม้แบบ / Silo อื่น ๆ | L19: 5 | M19: =SUM(F19:L19) -> 5 | N19: =M19/$M$91 -> 0.26315789
E20: B2.3 - งานติดตั้งอุปกรณ์สำนักงาน / กล้องวงจรปิด | M20: =SUM(F20:L20) -> 0 | N20: =M20/$M$91 -> 0
E21: B2.4 - งานเตรียมพื้นที่บริเวณรับประทานอาหาร, ลานปูน, ถนน, ทางเดิน, หลังคาคลุม | M21: =SUM(F21:L21) -> 0 | N21: =M21/$M$91 -> 0
E22: B2.5 - งานจัดเรียงวัสดุให้เป็นระเบียบ | M22: =SUM(F22:L22) -> 0 | N22: =M22/$M$91 -> 0
E23: B2.6 - งานปูแผ่นเหล็กทางเดิน | M23: =SUM(F23:L23) -> 0 | N23: =M23/$M$91 -> 0
E24: B2.7 - งานตั้ง TC / ลิฟต์ชั่วคราว / Silo | M24: =SUM(F24:L24) -> 0 | N24: =M24/$M$91 -> 0
E25: B2.8 - งานเทคอนกรีตชั่วคราวบริเวณพื้นที่ชั้น 1 | M25: =SUM(F25:L25) -> 0 | N25: =M25/$M$91 -> 0
E26: B2.9 - งานจัดเตรียมอื่น ๆ | M26: =SUM(F26:L26) -> 0 | N26: =M26/$M$91 -> 0
D27: B3 | E27: งานความสะอาดบริเวณชั้น 1 | M27: =SUM(F27:L27) -> 0 | N27: =M27/$M$91 -> 0
E28: B3.1 - ทำความสะอาดบริเวณชั้น 1 | M28: =SUM(F28:L28) -> 0 | N28: =M28/$M$91 -> 0
E29: B3.2 - สูบน้ำ / ล้างล้อ / กวาดถนน | M29: =SUM(F29:L29) -> 0 | N29: =M29/$M$91 -> 0
D30: B4 | E30: งานเก็บขยะ / ขนขยะ บริเวณชั้น 1 | M30: =SUM(F30:L30) -> 0 | N30: =M30/$M$91 -> 0
D31: B5 | E31: งานขนย้ายวัสดุบริเวณชั้น 1 | M31: =SUM(F31:L31) -> 0 | N31: =M31/$M$91 -> 0
E32: B5.1 - รับวัสดุ / ขนวัสดุลงจากรถ | M32: =SUM(F32:L32) -> 0 | N32: =M32/$M$91 -> 0
E33: B5.2 - ส่งวัสดุขึ้นรถขนส่ง ส่งกลับร้านค้า / DSC | M33: =SUM(F33:L33) -> 0 | N33: =M33/$M$91 -> 0
E34: B5.3 - ขนย้ายวัสดุในโครงการ | M34: =SUM(F34:L34) -> 0 | N34: =M34/$M$91 -> 0
D35: B6 | E35: งานบริการอื่น ๆ บริเวณชั้น 1 | M35: =SUM(F35:L35) -> 0 | N35: =M35/$M$91 -> 0
E36: B6.1 - งานโบกรถ / จราจร | M36: =SUM(F36:L36) -> 0 | N36: =M36/$M$91 -> 0
E37: B6.2 - งานทาสีกันสนิมเหล็กกล่อง / แป๊บกลม | M37: =SUM(F37:L37) -> 0 | N37: =M37/$M$91 -> 0
E38: B6.3 - งานสำนักงานขาย | M38: =SUM(F38:L38) -> 0 | N38: =M38/$M$91 -> 0
E39: B6.4 - งานทำห้องเก็บวัสดุ / ห้องตัวอย่าง Mockup | M39: =SUM(F39:L39) -> 0 | N39: =M39/$M$91 -> 0
E40: B6.5 - งานอื่น ๆ บริเวณชั้น 1 | M40: =SUM(F40:L40) -> 0 | N40: =M40/$M$91 -> 0
B41: C | C41: งานพื้นที่ในตัวอาคาร | D41: C1 | E41: งานความสะอาดตามชั้น | M41: =SUM(F41:L41) -> 0 | N41: =M41/$M$91 -> 0 | O41: =SUM(M41:M58) -> 0 | P41: =O41/O91 -> 0
...

Sheet May26
B2: จำนวนแรงงาน DC แยกตามหมวดงาน ประจำเดือน พฤษภาคม 2569
B3: หมวดงาน | D3: หมวดงานย่อย | F3: จำนวนแรงงาน (คน) | M3: รวม
M4: หมวดงานย่อย | O4: หมวดงาน
F5: A | G5: B | H5: C | I5: D | J5: E | K5: LA | L5: กองกลาง | M5: จำนวนคน | N5: % | O5: จำนวนคน | P5: %
B6: A | C6: งานประจำในไซต์งาน | D6: A1 | E6: งานเซอร์เวย์ / ตีไลน์ | L6: 3 | M6: =SUM(F6:L6) -> 3 | N6: =M6/$M$91 -> 0.15789474 | O6: =SUM(M6:M13) -> 5 | P6: =O6/O91 -> 0.26315789
D7: A2 | E7: งานสโตร์ / เช็กเกอร์ | M7: =SUM(F7:L7) -> 0 | N7: =M7/$M$91 -> 0
D8: A3 | E8: งานซ่อมบำรุง / บริการหน้างาน (ไฟฟ้า, ประปา) | L8: 1 | M8: =SUM(F8:L8) -> 1 | N8: =M8/$M$91 -> 0.052631579
D9: A4 | E9: งานแม่บ้าน / ทำความสะอาด | L9: 1 | M9: =SUM(F9:L9) -> 1 | N9: =M9/$M$91 -> 0.052631579
D10: A5 | E10: งานขับเครน /บอกเครน /เครื่องจักร /รถยนต์ | M10: =SUM(F10:L10) -> 0 | N10: =M10/$M$91 -> 0
E11: A5.1 - งานขับเครน / บอกเครน | M11: =SUM(F11:L11) -> 0 | N11: =M11/$M$91 -> 0
E12: A5.2 - ขับเครื่องจักร (ลิฟต์ / โฟล์คลิฟต์ / แบ็กโฮ ฯลฯ) | M12: =SUM(F12:L12) -> 0 | N12: =M12/$M$91 -> 0
E13: A5.3 - ขับรถยนต์ | M13: =SUM(F13:L13) -> 0 | N13: =M13/$M$91 -> 0
B14: B | C14: งานพื้นที่บริเวณชั้น 1 | D14: B1 | E14: งานป้องกันดินพัง / งานใต้ดิน | M14: =SUM(F14:L14) -> 0 | N14: =M14/$M$91 -> 0 | O14: =SUM(M14:M40) -> 10 | P14: =O14/O91 -> 0.52631579
E15: B1.1 - งานระบบป้องกันดินพัง | M15: =SUM(F15:L15) -> 0 | N15: =M15/$M$91 -> 0
E16: B1.2 - งานโครงสร้างใต้ดิน | M16: =SUM(F16:L16) -> 0 | N16: =M16/$M$91 -> 0
D17: B2 | E17: งานจัดเตรียมพื้นที่บริเวณชั้น 1 | M17: =SUM(F17:L17) -> 0 | N17: =M17/$M$91 -> 0
E18: B2.1 - งานเตรียมการ สำนักงาน, สโตร์, ห้องน้ำ, ป้าย, รั้ว, ป้อม, ประตู | L18: 5 | M18: =SUM(F18:L18) -> 5 | N18: =M18/$M$91 -> 0.26315789
E19: B2.2 - งานเตรียมพื้นที่กองวัสดุ / เหล็ก / ไม้แบบ / Silo อื่น ๆ | L19: 5 | M19: =SUM(F19:L19) -> 5 | N19: =M19/$M$91 -> 0.26315789
E20: B2.3 - งานติดตั้งอุปกรณ์สำนักงาน / กล้องวงจรปิด | M20: =SUM(F20:L20) -> 0 | N20: =M20/$M$91 -> 0
E21: B2.4 - งานเตรียมพื้นที่บริเวณรับประทานอาหาร, ลานปูน, ถนน, ทางเดิน, หลังคาคลุม | M21: =SUM(F21:L21) -> 0 | N21: =M21/$M$91 -> 0
E22: B2.5 - งานจัดเรียงวัสดุให้เป็นระเบียบ | M22: =SUM(F22:L22) -> 0 | N22: =M22/$M$91 -> 0
E23: B2.6 - งานปูแผ่นเหล็กทางเดิน | M23: =SUM(F23:L23) -> 0 | N23: =M23/$M$91 -> 0
E24: B2.7 - งานตั้ง TC / ลิฟต์ชั่วคราว / Silo | M24: =SUM(F24:L24) -> 0 | N24: =M24/$M$91 -> 0
E25: B2.8 - งานเทคอนกรีตชั่วคราวบริเวณพื้นที่ชั้น 1 | M25: =SUM(F25:L25) -> 0 | N25: =M25/$M$91 -> 0
E26: B2.9 - งานจัดเตรียมอื่น ๆ | M26: =SUM(F26:L26) -> 0 | N26: =M26/$M$91 -> 0
D27: B3 | E27: งานความสะอาดบริเวณชั้น 1 | M27: =SUM(F27:L27) -> 0 | N27: =M27/$M$91 -> 0
E28: B3.1 - ทำความสะอาดบริเวณชั้น 1 | M28: =SUM(F28:L28) -> 0 | N28: =M28/$M$91 -> 0
E29: B3.2 - สูบน้ำ / ล้างล้อ / กวาดถนน | M29: =SUM(F29:L29) -> 0 | N29: =M29/$M$91 -> 0
D30: B4 | E30: งานเก็บขยะ / ขนขยะ บริเวณชั้น 1 | M30: =SUM(F30:L30) -> 0 | N30: =M30/$M$91 -> 0
D31: B5 | E31: งานขนย้ายวัสดุบริเวณชั้น 1 | M31: =SUM(F31:L31) -> 0 | N31: =M31/$M$91 -> 0
E32: B5.1 - รับวัสดุ / ขนวัสดุลงจากรถ | M32: =SUM(F32:L32) -> 0 | N32: =M32/$M$91 -> 0
E33: B5.2 - ส่งวัสดุขึ้นรถขนส่ง ส่งกลับร้านค้า / DSC | M33: =SUM(F33:L33) -> 0 | N33: =M33/$M$91 -> 0
E34: B5.3 - ขนย้ายวัสดุในโครงการ | M34: =SUM(F34:L34) -> 0 | N34: =M34/$M$91 -> 0
D35: B6 | E35: งานบริการอื่น ๆ บริเวณชั้น 1 | M35: =SUM(F35:L35) -> 0 | N35: =M35/$M$91 -> 0
E36: B6.1 - งานโบกรถ / จราจร | M36: =SUM(F36:L36) -> 0 | N36: =M36/$M$91 -> 0
E37: B6.2 - งานทาสีกันสนิมเหล็กกล่อง / แป๊บกลม | M37: =SUM(F37:L37) -> 0 | N37: =M37/$M$91 -> 0
E38: B6.3 - งานสำนักงานขาย | M38: =SUM(F38:L38) -> 0 | N38: =M38/$M$91 -> 0
E39: B6.4 - งานทำห้องเก็บวัสดุ / ห้องตัวอย่าง Mockup | M39: =SUM(F39:L39) -> 0 | N39: =M39/$M$91 -> 0
E40: B6.5 - งานอื่น ๆ บริเวณชั้น 1 | M40: =SUM(F40:L40) -> 0 | N40: =M40/$M$91 -> 0
B41: C | C41: งานพื้นที่ในตัวอาคาร | D41: C1 | E41: งานความสะอาดตามชั้น | M41: =SUM(F41:L41) -> 0 | N41: =M41/$M$91 -> 0 | O41: =SUM(M41:M58) -> 0 | P41: =O41/O91 -> 0
...

Sheet Jun26
B2: จำนวนแรงงาน DC แยกตามหมวดงาน ประจำเดือน มิถุนายน 2569
B3: หมวดงาน | D3: หมวดงานย่อย | F3: จำนวนแรงงาน (คน) | M3: รวม
M4: หมวดงานย่อย | O4: หมวดงาน
F5: A | G5: B | H5: C | I5: D | J5: E | K5: LA | L5: กองกลาง | M5: จำนวนคน | N5: % | O5: จำนวนคน | P5: %
B6: A | C6: งานประจำในไซต์งาน | D6: A1 | E6: งานเซอร์เวย์ / ตีไลน์ | L6: 9 | M6: =SUM(F6:L6) -> 9 | N6: =M6/$M$91 -> 0.19148936 | O6: =SUM(M6:M13) -> 20 | P6: =O6/O91 -> 0.42553191
D7: A2 | E7: งานสโตร์ / เช็กเกอร์ | L7: 1 | M7: =SUM(F7:L7) -> 1 | N7: =M7/$M$91 -> 0.021276596
D8: A3 | E8: งานซ่อมบำรุง / บริการหน้างาน (ไฟฟ้า, ประปา) | L8: 4 | M8: =SUM(F8:L8) -> 4 | N8: =M8/$M$91 -> 0.085106383
D9: A4 | E9: งานแม่บ้าน / ทำความสะอาด | L9: 1 | M9: =SUM(F9:L9) -> 1 | N9: =M9/$M$91 -> 0.021276596
D10: A5 | E10: งานขับเครน /บอกเครน /เครื่องจักร /รถยนต์ | M10: =SUM(F10:L10) -> 0 | N10: =M10/$M$91 -> 0
E11: A5.1 - งานขับเครน / บอกเครน | L11: 4 | M11: =SUM(F11:L11) -> 4 | N11: =M11/$M$91 -> 0.085106383
E12: A5.2 - ขับเครื่องจักร (ลิฟต์ / โฟล์คลิฟต์ / แบ็กโฮ ฯลฯ) | M12: =SUM(F12:L12) -> 0 | N12: =M12/$M$91 -> 0
E13: A5.3 - ขับรถยนต์ | L13: 1 | M13: =SUM(F13:L13) -> 1 | N13: =M13/$M$91 -> 0.021276596
B14: B | C14: งานพื้นที่บริเวณชั้น 1 | D14: B1 | E14: งานป้องกันดินพัง / งานใต้ดิน | M14: =SUM(F14:L14) -> 0 | N14: =M14/$M$91 -> 0 | O14: =SUM(M14:M40) -> 17 | P14: =O14/O91 -> 0.36170213
E15: B1.1 - งานระบบป้องกันดินพัง | M15: =SUM(F15:L15) -> 0 | N15: =M15/$M$91 -> 0
E16: B1.2 - งานโครงสร้างใต้ดิน | M16: =SUM(F16:L16) -> 0 | N16: =M16/$M$91 -> 0
D17: B2 | E17: งานจัดเตรียมพื้นที่บริเวณชั้น 1 | M17: =SUM(F17:L17) -> 0 | N17: =M17/$M$91 -> 0
E18: B2.1 - งานเตรียมการ สำนักงาน, สโตร์, ห้องน้ำ, ป้าย, รั้ว, ป้อม, ประตู | M18: =SUM(F18:L18) -> 0 | N18: =M18/$M$91 -> 0
E19: B2.2 - งานเตรียมพื้นที่กองวัสดุ / เหล็ก / ไม้แบบ / Silo อื่น ๆ | M19: =SUM(F19:L19) -> 0 | N19: =M19/$M$91 -> 0
E20: B2.3 - งานติดตั้งอุปกรณ์สำนักงาน / กล้องวงจรปิด | M20: =SUM(F20:L20) -> 0 | N20: =M20/$M$91 -> 0
E21: B2.4 - งานเตรียมพื้นที่บริเวณรับประทานอาหาร, ลานปูน, ถนน, ทางเดิน, หลังคาคลุม | M21: =SUM(F21:L21) -> 0 | N21: =M21/$M$91 -> 0
E22: B2.5 - งานจัดเรียงวัสดุให้เป็นระเบียบ | M22: =SUM(F22:L22) -> 0 | N22: =M22/$M$91 -> 0
E23: B2.6 - งานปูแผ่นเหล็กทางเดิน | M23: =SUM(F23:L23) -> 0 | N23: =M23/$M$91 -> 0
E24: B2.7 - งานตั้ง TC / ลิฟต์ชั่วคราว / Silo | M24: =SUM(F24:L24) -> 0 | N24: =M24/$M$91 -> 0
E25: B2.8 - งานเทคอนกรีตชั่วคราวบริเวณพื้นที่ชั้น 1 | M25: =SUM(F25:L25) -> 0 | N25: =M25/$M$91 -> 0
E26: B2.9 - งานจัดเตรียมอื่น ๆ | M26: =SUM(F26:L26) -> 0 | N26: =M26/$M$91 -> 0
D27: B3 | E27: งานความสะอาดบริเวณชั้น 1 | M27: =SUM(F27:L27) -> 0 | N27: =M27/$M$91 -> 0
E28: B3.1 - ทำความสะอาดบริเวณชั้น 1 | L28: 2 | M28: =SUM(F28:L28) -> 2 | N28: =M28/$M$91 -> 0.042553191
E29: B3.2 - สูบน้ำ / ล้างล้อ / กวาดถนน | L29: 6 | M29: =SUM(F29:L29) -> 6 | N29: =M29/$M$91 -> 0.12765957
D30: B4 | E30: งานเก็บขยะ / ขนขยะ บริเวณชั้น 1 | M30: =SUM(F30:L30) -> 0 | N30: =M30/$M$91 -> 0
D31: B5 | E31: งานขนย้ายวัสดุบริเวณชั้น 1 | M31: =SUM(F31:L31) -> 0 | N31: =M31/$M$91 -> 0
E32: B5.1 - รับวัสดุ / ขนวัสดุลงจากรถ | L32: 3 | M32: =SUM(F32:L32) -> 3 | N32: =M32/$M$91 -> 0.063829787
E33: B5.2 - ส่งวัสดุขึ้นรถขนส่ง ส่งกลับร้านค้า / DSC | M33: =SUM(F33:L33) -> 0 | N33: =M33/$M$91 -> 0
E34: B5.3 - ขนย้ายวัสดุในโครงการ | L34: 2 | M34: =SUM(F34:L34) -> 2 | N34: =M34/$M$91 -> 0.042553191
D35: B6 | E35: งานบริการอื่น ๆ บริเวณชั้น 1 | M35: =SUM(F35:L35) -> 0 | N35: =M35/$M$91 -> 0
E36: B6.1 - งานโบกรถ / จราจร | L36: 4 | M36: =SUM(F36:L36) -> 4 | N36: =M36/$M$91 -> 0.085106383
E37: B6.2 - งานทาสีกันสนิมเหล็กกล่อง / แป๊บกลม | M37: =SUM(F37:L37) -> 0 | N37: =M37/$M$91 -> 0
E38: B6.3 - งานสำนักงานขาย | M38: =SUM(F38:L38) -> 0 | N38: =M38/$M$91 -> 0
E39: B6.4 - งานทำห้องเก็บวัสดุ / ห้องตัวอย่าง Mockup | M39: =SUM(F39:L39) -> 0 | N39: =M39/$M$91 -> 0
E40: B6.5 - งานอื่น ๆ บริเวณชั้น 1 | M40: =SUM(F40:L40) -> 0 | N40: =M40/$M$91 -> 0
B41: C | C41: งานพื้นที่ในตัวอาคาร | D41: C1 | E41: งานความสะอาดตามชั้น | M41: =SUM(F41:L41) -> 0 | N41: =M41/$M$91 -> 0 | O41: =SUM(M41:M58) -> 4 | P41: =O41/O91 -> 0.085106383
...

Sheet Jul26
B2: จำนวนแรงงาน DC แยกตามหมวดงาน ประจำเดือน กรกฎาคม 2569
B3: หมวดงาน | D3: หมวดงานย่อย | F3: จำนวนแรงงาน (คน) | M3: รวม
M4: หมวดงานย่อย | O4: หมวดงาน
F5: A | G5: B | H5: C | I5: D | J5: E | K5: LA | L5: กองกลาง | M5: จำนวนคน | N5: % | O5: จำนวนคน | P5: %
B6: A | C6: งานประจำในไซต์งาน | D6: A1 | E6: งานเซอร์เวย์ / ตีไลน์ | L6: 9 | M6: =SUM(F6:L6) -> 9 | N6: =M6/$M$91 -> 0.2 | O6: =SUM(M6:M13) -> 21 | P6: =O6/O91 -> 0.46666667
D7: A2 | E7: งานสโตร์ / เช็กเกอร์ | L7: 1 | M7: =SUM(F7:L7) -> 1 | N7: =M7/$M$91 -> 0.022222222
D8: A3 | E8: งานซ่อมบำรุง / บริการหน้างาน (ไฟฟ้า, ประปา) | L8: 4 | M8: =SUM(F8:L8) -> 4 | N8: =M8/$M$91 -> 0.088888889
D9: A4 | E9: งานแม่บ้าน / ทำความสะอาด | L9: 2 | M9: =SUM(F9:L9) -> 2 | N9: =M9/$M$91 -> 0.044444444
D10: A5 | E10: งานขับเครน /บอกเครน /เครื่องจักร /รถยนต์ | M10: =SUM(F10:L10) -> 0 | N10: =M10/$M$91 -> 0
E11: A5.1 - งานขับเครน / บอกเครน | L11: 4 | M11: =SUM(F11:L11) -> 4 | N11: =M11/$M$91 -> 0.088888889
E12: A5.2 - ขับเครื่องจักร (ลิฟต์ / โฟล์คลิฟต์ / แบ็กโฮ ฯลฯ) | M12: =SUM(F12:L12) -> 0 | N12: =M12/$M$91 -> 0
E13: A5.3 - ขับรถยนต์ | L13: 1 | M13: =SUM(F13:L13) -> 1 | N13: =M13/$M$91 -> 0.022222222
B14: B | C14: งานพื้นที่บริเวณชั้น 1 | D14: B1 | E14: งานป้องกันดินพัง / งานใต้ดิน | M14: =SUM(F14:L14) -> 0 | N14: =M14/$M$91 -> 0 | O14: =SUM(M14:M40) -> 17 | P14: =O14/O91 -> 0.37777778
E15: B1.1 - งานระบบป้องกันดินพัง | M15: =SUM(F15:L15) -> 0 | N15: =M15/$M$91 -> 0
E16: B1.2 - งานโครงสร้างใต้ดิน | M16: =SUM(F16:L16) -> 0 | N16: =M16/$M$91 -> 0
D17: B2 | E17: งานจัดเตรียมพื้นที่บริเวณชั้น 1 | M17: =SUM(F17:L17) -> 0 | N17: =M17/$M$91 -> 0
E18: B2.1 - งานเตรียมการ สำนักงาน, สโตร์, ห้องน้ำ, ป้าย, รั้ว, ป้อม, ประตู | M18: =SUM(F18:L18) -> 0 | N18: =M18/$M$91 -> 0
E19: B2.2 - งานเตรียมพื้นที่กองวัสดุ / เหล็ก / ไม้แบบ / Silo อื่น ๆ | M19: =SUM(F19:L19) -> 0 | N19: =M19/$M$91 -> 0
E20: B2.3 - งานติดตั้งอุปกรณ์สำนักงาน / กล้องวงจรปิด | M20: =SUM(F20:L20) -> 0 | N20: =M20/$M$91 -> 0
E21: B2.4 - งานเตรียมพื้นที่บริเวณรับประทานอาหาร, ลานปูน, ถนน, ทางเดิน, หลังคาคลุม | M21: =SUM(F21:L21) -> 0 | N21: =M21/$M$91 -> 0
E22: B2.5 - งานจัดเรียงวัสดุให้เป็นระเบียบ | M22: =SUM(F22:L22) -> 0 | N22: =M22/$M$91 -> 0
E23: B2.6 - งานปูแผ่นเหล็กทางเดิน | M23: =SUM(F23:L23) -> 0 | N23: =M23/$M$91 -> 0
E24: B2.7 - งานตั้ง TC / ลิฟต์ชั่วคราว / Silo | M24: =SUM(F24:L24) -> 0 | N24: =M24/$M$91 -> 0
E25: B2.8 - งานเทคอนกรีตชั่วคราวบริเวณพื้นที่ชั้น 1 | M25: =SUM(F25:L25) -> 0 | N25: =M25/$M$91 -> 0
E26: B2.9 - งานจัดเตรียมอื่น ๆ | M26: =SUM(F26:L26) -> 0 | N26: =M26/$M$91 -> 0
D27: B3 | E27: งานความสะอาดบริเวณชั้น 1 | M27: =SUM(F27:L27) -> 0 | N27: =M27/$M$91 -> 0
E28: B3.1 - ทำความสะอาดบริเวณชั้น 1 | L28: 2 | M28: =SUM(F28:L28) -> 2 | N28: =M28/$M$91 -> 0.044444444
E29: B3.2 - สูบน้ำ / ล้างล้อ / กวาดถนน | L29: 6 | M29: =SUM(F29:L29) -> 6 | N29: =M29/$M$91 -> 0.13333333
D30: B4 | E30: งานเก็บขยะ / ขนขยะ บริเวณชั้น 1 | M30: =SUM(F30:L30) -> 0 | N30: =M30/$M$91 -> 0
D31: B5 | E31: งานขนย้ายวัสดุบริเวณชั้น 1 | M31: =SUM(F31:L31) -> 0 | N31: =M31/$M$91 -> 0
E32: B5.1 - รับวัสดุ / ขนวัสดุลงจากรถ | L32: 3 | M32: =SUM(F32:L32) -> 3 | N32: =M32/$M$91 -> 0.066666667
E33: B5.2 - ส่งวัสดุขึ้นรถขนส่ง ส่งกลับร้านค้า / DSC | M33: =SUM(F33:L33) -> 0 | N33: =M33/$M$91 -> 0
E34: B5.3 - ขนย้ายวัสดุในโครงการ | L34: 2 | M34: =SUM(F34:L34) -> 2 | N34: =M34/$M$91 -> 0.044444444
D35: B6 | E35: งานบริการอื่น ๆ บริเวณชั้น 1 | M35: =SUM(F35:L35) -> 0 | N35: =M35/$M$91 -> 0
E36: B6.1 - งานโบกรถ / จราจร | L36: 4 | M36: =SUM(F36:L36) -> 4 | N36: =M36/$M$91 -> 0.088888889
E37: B6.2 - งานทาสีกันสนิมเหล็กกล่อง / แป๊บกลม | M37: =SUM(F37:L37) -> 0 | N37: =M37/$M$91 -> 0
E38: B6.3 - งานสำนักงานขาย | M38: =SUM(F38:L38) -> 0 | N38: =M38/$M$91 -> 0
E39: B6.4 - งานทำห้องเก็บวัสดุ / ห้องตัวอย่าง Mockup | M39: =SUM(F39:L39) -> 0 | N39: =M39/$M$91 -> 0
E40: B6.5 - งานอื่น ๆ บริเวณชั้น 1 | M40: =SUM(F40:L40) -> 0 | N40: =M40/$M$91 -> 0
B41: C | C41: งานพื้นที่ในตัวอาคาร | D41: C1 | E41: งานความสะอาดตามชั้น | M41: =SUM(F41:L41) -> 0 | N41: =M41/$M$91 -> 0 | O41: =SUM(M41:M58) -> 0 | P41: =O41/O91 -> 0
...
